<?xml version='1.0'?>
<sdf version="1.4">
	<model name="tigrillo">
		<static>false</static>
		
		<!-- Create the solid for body-->
		<link name="body">
			
			<pose>0 0 0.08952 0 0 0 </pose>
			
			<!-- All mass and inertial features -->
			<inertial>
				<mass>1.0</mass>
				<inertia>
					<ixx>0.002167</ixx>
					<ixy>0.0</ixy>
					<ixz>0.0</ixz>
					<iyy>0.000833</iyy>
					<iyz>0.0</iyz>
					<izz>0.002833</izz>
				</inertia>
			</inertial>
			
			<!-- Geometric features for collision of main body -->
			<collision name="body_col">
				<geometry>
					<box>
						<size>0.15 0.25 0.05</size>
					</box>
				</geometry>
			</collision>
			
			<!-- Geometric and texture features for visuals of main body-->
			<visual name="body_vis">
				<geometry>
					<box>
						<size>0.15 0.25 0.05</size>
					</box>
				</geometry>
        <material>
          <script>
            <uri>file://media/materials/scripts/gazebo.material</uri>
            <name>Gazebo/Orange</name>
          </script>
        </material>
			</visual>

		</link>
		
		<!-- Solid for the right humerus -->
		<link name="right_humerus">
			
			<pose>0.08 0.10979 0.0578 0.4363 0 0</pose>
			
			<inertial>
				<mass>0.1</mass>
				<inertia>
					<ixx>0.0000411</ixx>
					<ixy>0.0</ixy>
					<ixz>0.0</ixz>
					<iyy>0.0000411</iyy>
					<iyz>0.0</iyz>
					<izz>0.00000045</izz>
				</inertia>
			</inertial>
			
			<collision name="col">
				<geometry>
					<cylinder>
						<radius>.003</radius>
						<length>0.07</length>
					</cylinder>
				</geometry>
			</collision>
			
			<visual name="vis">
				<geometry>
					<cylinder>
						<radius>.003</radius>
						<length>0.07</length>
					</cylinder>
				</geometry>
				<material>
				  <script>
				    <uri>file://media/materials/scripts/gazebo.material</uri>
				    <name>Gazebo/Turquoise</name>
				  </script>
				</material>
			</visual>
		</link>
		
		<!-- Solid for the right radius -->
		<link name="right_radius">
			
			<pose>0.08 0.13098 0.02217 1.022 0 0</pose>
			
			<inertial>
				<mass>0.1</mass>
				<inertia>
					<ixx>0.0000411</ixx>
					<ixy>0.0</ixy>
					<ixz>0.0</ixz>
					<iyy>0.0000411</iyy>
					<iyz>0.0</iyz>
					<izz>0.00000045</izz>
				</inertia>
			</inertial>
	
			<collision name="col_rad">
				<geometry>
					<cylinder>
						<radius>.003</radius>
						<length>0.085</length>
					</cylinder>
				</geometry>
				<surface>
					<friction>
						<ode>
							<mu>1</mu>
							<mu2>1</mu2>
						</ode>
						<bullet>
							<friction>1</friction>
							<friction2>1</friction2>
						</bullet>
					</friction>
				</surface>
			</collision>
			
			<visual name="vis_rad">
				<geometry>
					<cylinder>
						<radius>.003</radius>
						<length>0.085</length>
					</cylinder>
				</geometry>
				<material>
				  <script>
				    <uri>file://media/materials/scripts/gazebo.material</uri>
				    <name>Gazebo/Turquoise</name>
				  </script>
				</material>
			</visual>
			
			<collision name="col_foot">
				<pose>0 0.00261 -0.04676 0.5488 0 0</pose>
				<geometry>
					<box>
						<size>0.02 0.01 0.01</size>
					</box>
				</geometry>
				<surface>
					<friction>
						<ode>
							<mu>20000</mu>
							<mu2>20000</mu2>
						</ode>
						<bullet>
							<friction>2</friction>
							<friction2>2</friction2>
						</bullet>
					</friction>
					<contact>
					  <ode><min_depth>0.003</min_depth></ode>
					</contact>
				</surface>
			</collision>
			
			<visual name="vis_foot">
				<pose>0 0.00261 -0.04676 0.5488 0 0</pose>
				<geometry>
					<box>
						<size>0.02 0.01 0.01</size>
					</box>
				</geometry>
				<material>
				  <script>
				    <uri>file://media/materials/scripts/gazebo.material</uri>
				    <name>Gazebo/Red</name>
				  </script>
				</material>
			</visual>
		</link>
		
		<!-- Solid for the left humerus -->
		<link name="left_humerus">
			
			<pose>-0.08 0.10979 0.0578 0.4363 0 0</pose>
			
			<inertial>
				<mass>0.1</mass>
				<inertia>
					<ixx>0.0000411</ixx>
					<ixy>0.0</ixy>
					<ixz>0.0</ixz>
					<iyy>0.0000411</iyy>
					<iyz>0.0</iyz>
					<izz>0.00000045</izz>
				</inertia>
			</inertial>
			
			<collision name="col">
				<geometry>
					<cylinder>
						<radius>.003</radius>
						<length>0.07</length>
					</cylinder>
				</geometry>
			</collision>
			
			<visual name="vis">
				<geometry>
					<cylinder>
						<radius>.003</radius>
						<length>0.07</length>
					</cylinder>
				</geometry>
				<material>
				  <script>
				    <uri>file://media/materials/scripts/gazebo.material</uri>
				    <name>Gazebo/Turquoise</name>
				  </script>
				</material>
			</visual>
		</link>
		
		<!-- Solid for the left radius -->
		<link name="left_radius">
			
			<pose>-0.08 0.13098 0.02217 1.022 0 0</pose>
			
			<inertial>
				<mass>0.1</mass>
				<inertia>
					<ixx>0.0000411</ixx>
					<ixy>0.0</ixy>
					<ixz>0.0</ixz>
					<iyy>0.0000411</iyy>
					<iyz>0.0</iyz>
					<izz>0.00000045</izz>
				</inertia>
			</inertial>
						
			<collision name="col_rad">
				<geometry>
					<cylinder>
						<radius>.003</radius>
						<length>0.085</length>
					</cylinder>
				</geometry>
				<surface>
					<friction>
						<ode>
							<mu>1</mu>
							<mu2>1</mu2>
						</ode>
						<bullet>
							<friction>1</friction>
							<friction2>1</friction2>
						</bullet>
					</friction>
				</surface>
			</collision>
			
			<visual name="vis_rad">
				<geometry>
					<cylinder>
						<radius>.003</radius>
						<length>0.085</length>
					</cylinder>
				</geometry>
				<material>
				  <script>
				    <uri>file://media/materials/scripts/gazebo.material</uri>
				    <name>Gazebo/Turquoise</name>
				  </script>
				</material>
			</visual>
			
			<collision name="col_foot">

				<pose>0 0.00261 -0.04676 0.5488 0 0</pose>
				<geometry>
					<box>
						<size>0.02 0.01 0.01</size>
					</box>
				</geometry>
				<surface>
					<friction>
						<ode>
							<mu>20000</mu>
							<mu2>20000</mu2>
						</ode>
						<bullet>
							<friction>2</friction>
							<friction2>2</friction2>
						</bullet>
					</friction>
					<contact>
					  <ode><min_depth>0.003</min_depth></ode>
					</contact>
				</surface>
			</collision>
			
			<visual name="vis_foot">
				<pose>0 0.00261 -0.04676 0.5488 0 0</pose>
				<geometry>
					<box>
						<size>0.02 0.01 0.01</size>
					</box>
				</geometry>
				<material>
				  <script>
				    <uri>file://media/materials/scripts/gazebo.material</uri>
				    <name>Gazebo/Red</name>
				  </script>
				</material>
			</visual>
		</link>
		
		<!-- Solid for the right femur -->
		<link name="right_femur">
			
			<pose>0.08 -0.08021 0.0578 0.4363 0 0</pose>
			
			<inertial>
				<mass>0.1</mass>
				<inertia>
					<ixx>0.0000411</ixx>
					<ixy>0.0</ixy>
					<ixz>0.0</ixz>
					<iyy>0.0000411</iyy>
					<iyz>0.0</iyz>
					<izz>0.00000045</izz>
				</inertia>
			</inertial>
			
			<collision name="col">
				<geometry>
					<cylinder>
						<radius>.003</radius>
						<length>0.07</length>
					</cylinder>
				</geometry>
			</collision>
			
			<visual name="vis">
				<geometry>
					<cylinder>
						<radius>.003</radius>
						<length>0.07</length>
					</cylinder>
				</geometry>
				<material>
				  <script>
				    <uri>file://media/materials/scripts/gazebo.material</uri>
				    <name>Gazebo/Turquoise</name>
				  </script>
				</material>
			</visual>
		</link>
		
		<!-- Solid for the right tibia -->
		<link name="right_tibia">
			
			<pose>0.08 -0.05902 0.02217 1.022 0 0</pose>
			
			<inertial>
				<mass>0.1</mass>
				<inertia>
					<ixx>0.0000411</ixx>
					<ixy>0.0</ixy>
					<ixz>0.0</ixz>
					<iyy>0.0000411</iyy>
					<iyz>0.0</iyz>
					<izz>0.00000045</izz>
				</inertia>
			</inertial>
						
			<collision name="col_tib">
				<geometry>
					<cylinder>
						<radius>.003</radius>
						<length>0.085</length>
					</cylinder>
				</geometry>
				<surface>
					<friction>
						<ode>
							<mu>2</mu>
							<mu2>2</mu2>
						</ode>
						<bullet>
							<friction>2</friction>
							<friction2>2</friction2>
						</bullet>
					</friction>
				</surface>
			</collision>
			
			<visual name="vis_tib">
				<geometry>
					<cylinder>
						<radius>.003</radius>
						<length>0.085</length>
					</cylinder>
				</geometry>
				<material>
				  <script>
				    <uri>file://media/materials/scripts/gazebo.material</uri>
				    <name>Gazebo/Turquoise</name>
				  </script>
				</material>
			</visual>
			
			<collision name="col_foot">
				<pose>0 0.00261 -0.04676 0.5488 0 0</pose>
				<geometry>
					<box>
						<size>0.02 0.01 0.01</size>
					</box>
				</geometry>
				<surface>
					<friction>
						<ode>
							<mu>20000</mu>
							<mu2>20000</mu2>
						</ode>
						<bullet>
							<friction>2</friction>
							<friction2>2</friction2>
						</bullet>
					</friction>
					<contact>
					  <ode><min_depth>0.003</min_depth></ode>
					</contact>
				</surface>
			</collision>
			
			<visual name="vis_foot">
				<pose>0 0.00261 -0.04676 0.5488 0 0</pose>
				<geometry>
					<box>
						<size>0.02 0.01 0.01</size>
					</box>
				</geometry>
				<material>
				  <script>
				    <uri>file://media/materials/scripts/gazebo.material</uri>
				    <name>Gazebo/Red</name>
				  </script>
				</material>
			</visual>
		</link>		
		
		<!-- Solid for the left femur -->
		<link name="left_femur">
			
			<pose>-0.08 -0.08021 0.0578 0.4363 0 0</pose>
			
			<inertial>
				<mass>0.1</mass>
				<inertia>
					<ixx>0.0000411</ixx>
					<ixy>0.0</ixy>
					<ixz>0.0</ixz>
					<iyy>0.0000411</iyy>
					<iyz>0.0</iyz>
					<izz>0.00000045</izz>
				</inertia>
			</inertial>
			
			<collision name="col">
				<geometry>
					<cylinder>
						<radius>.003</radius>
						<length>0.07</length>
					</cylinder>
				</geometry>
			</collision>
			
			<visual name="vis">
				<geometry>
					<cylinder>
						<radius>.003</radius>
						<length>0.07</length>
					</cylinder>
				</geometry>
				<material>
				  <script>
				    <uri>file://media/materials/scripts/gazebo.material</uri>
				    <name>Gazebo/Turquoise</name>
				  </script>
				</material>
			</visual>
		</link>
		
		<!-- Solid for the left tibia -->
		<link name="left_tibia">
			
			<pose>-0.08 -0.05902 0.02217 1.022 0 0</pose>
			
			<inertial>
				<mass>0.1</mass>
				<inertia>
					<ixx>0.0000411</ixx>
					<ixy>0.0</ixy>
					<ixz>0.0</ixz>
					<iyy>0.0000411</iyy>
					<iyz>0.0</iyz>
					<izz>0.00000045</izz>
				</inertia>
			</inertial>
						
			<collision name="col_tib">
				<geometry>
					<cylinder>
						<radius>.003</radius>
						<length>0.085</length>
					</cylinder>
				</geometry>
				<surface>
					<friction>
						<ode>
							<mu>2</mu>
							<mu2>2</mu2>
						</ode>
						<bullet>
							<friction>2</friction>
							<friction2>2</friction2>
						</bullet>
					</friction>
				</surface>
			</collision>
			
			<visual name="vis_tib">
				<geometry>
					<cylinder>
						<radius>.003</radius>
						<length>0.085</length>
					</cylinder>
				</geometry>
				<material>
				  <script>
				    <uri>file://media/materials/scripts/gazebo.material</uri>
				    <name>Gazebo/Turquoise</name>
				  </script>
				</material>
			</visual>
			
			<collision name="col_foot">
				<pose>0 0.00261 -0.04676 0.5488 0 0</pose>
				<geometry>
					<box>
						<size>0.02 0.01 0.01</size>
					</box>
				</geometry>
				<surface>
					<friction>
						<ode>
							<mu>20000</mu>
							<mu2>20000</mu2>
						</ode>
						<bullet>
							<friction>2</friction>
							<friction2>2</friction2>
						</bullet>
					</friction>
					<contact>
					  <ode><min_depth>0.003</min_depth></ode>
					</contact>
				</surface>
			</collision>
			
			<visual name="vis_foot">
				<pose>0 0.00261 -0.04676 0.5488 0 0</pose>
				<geometry>
					<box>
						<size>0.02 0.01 0.01</size>
					</box>
				</geometry>
				<material>
				  <script>
				    <uri>file://media/materials/scripts/gazebo.material</uri>
				    <name>Gazebo/Red</name>
				  </script>
				</material>
			</visual>
		</link>

		<!-- rotation joint for the right shoulder -->
		<joint name="right_shoulder" type="revolute">
			<parent>body</parent>
			<child>right_humerus</child>
			<pose>0 0 0.035 0 0 0</pose>
			<axis>
				<xyz>1 0 0</xyz>
				<limit>
					<lower>-1.2</lower>
					<upper>1.2</upper>
				</limit>
			</axis>
		</joint>
		
		<!-- rotation joint for the left shoulder -->
		<joint name="left_shoulder" type="revolute">
			<parent>body</parent>
			<child>left_humerus</child>
			<pose>0 0 0.035 0 0 0</pose>
			<axis>
				<xyz>1 0 0</xyz>
				<limit>
					<lower>-1.2</lower>
					<upper>1.2</upper>
				</limit>
			</axis>
		</joint>
		
		<!-- rotation joint for the right hip -->
		<joint name="right_hip" type="revolute">
			<parent>body</parent>
			<child>right_femur</child>
			<pose>0 0 0.035 0 0 0</pose>
			<axis>
				<xyz>1 0 0</xyz>
				<limit>
					<lower>-1.2</lower>
					<upper>1.2</upper>
				</limit>
			</axis>
		</joint>
		
		<!-- rotation joint for the left hip -->
		<joint name="left_hip" type="revolute">
			<parent>body</parent>
			<child>left_femur</child>
			<pose>0 0 0.035 0 0 0</pose>
			<axis>
				<xyz>1 0 0</xyz>
				<limit>
					<lower>-1.2</lower>
					<upper>1.2</upper>
				</limit>
			</axis>
		</joint>

	<!-- rotation joint for the right elbow -->
		<joint name="right_elbow" type="revolute">
			<parent>right_humerus</parent>
			<child>right_radius</child>
			<pose>0 0 0.01 0 0 0</pose>
			<axis>
				<xyz>1 0 0</xyz>
				<dynamics>
					<damping>0.05</damping>
					<spring_stiffness>1.0</spring_stiffness>
				</dynamics>
				<limit>
					<lower>-3.0</lower>
					<upper>3.0</upper>
				</limit>
			</axis>

					
		</joint>
		
		<!-- rotation joint for the left elbow -->
		<joint name="left_elbow" type="revolute">
			<parent>left_humerus</parent>
			<child>left_radius</child>
			<pose>0 0 0.01 0 0 0</pose>
			<axis>
				<xyz>1 0 0</xyz>
				<dynamics>
					<damping>0.05</damping>
					<spring_stiffness>1.0</spring_stiffness>
				</dynamics>
				<limit>
					<lower>-3.0</lower>
					<upper>3.0</upper>
				</limit>
			</axis>
	
					
		</joint>
		
		<!-- rotation joint for the right knee -->
		<joint name="right_knee" type="revolute">
			<parent>right_femur</parent>
			<child>right_tibia</child>
			<pose>0 0 0.01 0 0 0</pose>
			<axis>
				<xyz>1 0 0</xyz>

				<limit>
					<lower>-3.0</lower>
					<upper>3.0</upper>
				</limit>
				<dynamics>
					<damping>0.05</damping>
					<spring_stiffness>1.0</spring_stiffness>
				</dynamics>
			</axis>

					
		</joint>
		
		<!-- rotation joint for the left knee -->
		<joint name="left_knee" type="revolute">
			<parent>left_femur</parent>
			<child>left_tibia</child>
			<pose>0 0 0.01 0 0 0</pose>
			<axis>
				<xyz>1 0 0</xyz>

				<limit>
					<lower>-3.0</lower>
					<upper>3.0</upper>
				</limit>
				<dynamics>
					<damping>0.05</damping>
					<spring_stiffness>1.0</spring_stiffness>
				</dynamics>
			</axis>

		</joint>
	<!-- Attach the plugin to this model -->
	<plugin name='generic_controller' filename='libgeneric_controller_plugin.so'>
		<!--<controller joint_name="left_shoulder">
			<type>position</type>
			<pid>50.0 100.0 5.0</pid>
		</controller>
		<controller joint_name="right_shoulder">
			<type>position</type>
			<pid>50.0 100.0 5.0</pid>
		</controller>
		<controller joint_name="left_hip">
			<type>position</type>
			<pid>50.0 100.0 5.0</pid>
		</controller>
		<controller joint_name="right_hip">
			<type>position</type>
			<pid>50.0 100.0 5.0</pid>
		</controller> -->

		<controller joint_name="left_shoulder">
			<type>position</type>
			<pid>10. 0.0 0.0</pid>
		</controller>
		<controller joint_name="right_shoulder">
			<type>position</type>
			<pid>10. 0.0 0.0</pid>
		</controller>
		<controller joint_name="left_hip">
			<type>position</type>
			<pid>10. 0.0 0.0</pid>
		</controller>
		<controller joint_name="right_hip">
			<type>position</type>
			<pid>10.0 0.0 0.0</pid>
		</controller>
	</plugin>
    </model>
</sdf>
