<mujoco model="quadruped">
  <compiler angle="degree" coordinate="global" inertiafromgeom="true"/>
  <option gravity="0 0 -98.1"/>
  <default>
    <geom density="1" rgba=".9 .7 .1 1" size="0.05"/>
    <site rgba=".9 .9 .9 1" size="0.005" type="sphere"/>
    <joint axis="1 0 0" limited="true" range="-100 100" solimplimit="0.95 0.95 0.1" type="hinge"/>
    <tendon limited="true" range="0.25 1" rgba=".95 .3 .3 1" stiffness="4000" width="0.02"/>
  </default>
  <asset>
    <texture builtin="gradient" height="128" rgb1=".4 .6 .8" rgb2="0 0 0" type="skybox" width="128"/>
    <texture builtin="flat" height="1278" mark="cross" markrgb="1 1 1" name="texgeom" random="0.01" rgb1="0.8 0.6 0.4" rgb2="0.8 0.6 0.4" type="cube" width="127"/>
    <texture builtin="checker" height="512" name="texplane" rgb1=".2 .3 .4" rgb2=".1 0.15 0.2" type="2d" width="512"/>
    <material name="MatPlane" reflectance="0" texrepeat="1 1" texture="texplane" texuniform="true"/>
    <material name="geom" texture="texgeom" texuniform="true"/>
  </asset>
  <worldbody>
    <geom condim="3" material="MatPlane" name="floor" pos="0 0 0" size="50 50 .125" type="plane"/>
    <body name="torso">
      <geom mass="0.17900" pos="0.00000 -0.80000 1.51967" size="0.70000 0.40000 0.15000" type="box"/>
      <geom mass="0.03000" pos="0.00000 0.00000 1.38217" size="0.25000 0.40000 0.01250" type="box" name="torso_geom"/>
      <geom mass="0.17900" pos="0.00000 0.70000 1.49467" size="0.45000 0.30000 0.12500" type="box"/>
      <joint limited="false" name="gravity" type="free"/>
      <site name="sensor_torso" pos="0 0 1.36967"/>
      <body>
        <geom mass="0.067" pos="0.52000 -0.80000 1.11667" size="0.18000 0.18000 0.25300" type="box"/>
        <body>
          <geom fromto="0.75100 -0.80000 1.03967 0.75100 -1.09583 0.40525" type="capsule"/>
          <joint damping="0.2" name="shoulder_1" pos="0.75100 -0.80000 1.03967"/>
          <site name="s1_1" pos="0.75100 -0.90565 0.81309"/>
          <body>
            <geom fromto="0.85600 -0.79723 0.58783 0.85600 -1.52241 0.14443" type="capsule"/>
            <joint damping="0.2" limited="true" pos="0.75100 -1.09583 0.40525" range="-60 0"/>
            <site name="s1_2" pos="0.85600 -0.79723 0.58783"/>
            <body pos="0.85600 -1.52241 0.14443">
              <geom friction="1 0.005 0.0001" fromto="0.85600 -1.52241 0.14443 0.85600 -1.54241 0.10443" type="capsule"/>
              <site name="sensor_1" pos="0.85600 -1.52241 0.14443"/>
            </body>
          </body>
        </body>
      </body>
      <body>
        <geom mass="0.067" pos="-0.52000 -0.80000 1.11667" size="0.18000 0.18000 0.25300" type="box"/>
        <body>
          <geom fromto="-0.75100 -0.80000 1.03967 -0.75100 -1.09583 0.40525" type="capsule"/>
          <joint damping="0.2" name="shoulder_2" pos="-0.75100 -0.80000 1.03967"/>
          <site name="s2_1" pos="-0.75100 -0.90565 0.81309"/>
          <body>
            <geom fromto="-0.85600 -0.79723 0.58783 -0.85600 -1.52241 0.14443" type="capsule"/>
            <joint damping="0.2" limited="true" pos="-0.75100 -1.09583 0.40525" range="-60 0"/>
            <site name="s2_2" pos="-0.85600 -0.79723 0.58783"/>
            <body pos="-0.85600 -1.52241 0.14443">
              <geom friction="1 0.005 0.0001" fromto="-0.85600 -1.52241 0.14443 -0.85600 -1.54241 0.10443" type="capsule"/>
              <site name="sensor_2" pos="-0.85600 -1.52241 0.14443"/>
            </body>
          </body>
        </body>
      </body>
      <body>
        <geom mass="0.067" pos="0.27000 0.70000 1.11667" size="0.18000 0.18000 0.25300" type="box"/>
        <body>
          <geom fromto="0.50100 0.70000 1.03967 0.50100 0.70000 0.33967" type="capsule"/>
          <joint damping="0.2" name="shoulder_3" pos="0.50100 0.70000 1.03967"/>
          <site name="s3_1" pos="0.50100 0.70000 0.78967"/>
          <body>
            <geom fromto="0.60600 0.89347 0.63133 0.60600 0.42361 -0.07700" type="capsule"/>
            <joint damping="0.2" limited="true" pos="0.50100 0.70000 0.33967" range="-60 0"/>
            <site name="s3_2" pos="0.60600 0.89347 0.63133"/>
            <body pos="0.60600 0.42361 -0.07700">
              <geom friction="1 0.005 0.0001" fromto="0.60600 0.42361 -0.07700 0.60600 0.40361 -0.11700" type="capsule"/>
              <site name="sensor_3" pos="0.60600 0.42361 -0.07700"/>
            </body>
          </body>
        </body>
      </body>
      <body>
        <geom mass="0.067" pos="-0.27000 0.70000 1.11667" size="0.18000 0.18000 0.25300" type="box"/>
        <body>
          <geom fromto="-0.50100 0.70000 1.03967 -0.50100 0.70000 0.33967" type="capsule"/>
          <joint damping="0.2" name="shoulder_4" pos="-0.50100 0.70000 1.03967"/>
          <site name="s4_1" pos="-0.50100 0.70000 0.78967"/>
          <body>
            <geom fromto="-0.60600 0.89347 0.63133 -0.60600 0.42361 -0.07700" type="capsule"/>
            <joint damping="0.2" limited="true" pos="-0.50100 0.70000 0.33967" range="-60 0"/>
            <site name="s4_2" pos="-0.60600 0.89347 0.63133"/>
            <body pos="-0.60600 0.42361 -0.07700">
              <geom friction="1 0.005 0.0001" fromto="-0.60600 0.42361 -0.07700 -0.60600 0.40361 -0.11700" type="capsule"/>
              <site name="sensor_4" pos="-0.60600 0.42361 -0.07700"/>
            </body>
          </body>
        </body>
      </body>
      <body name="battery_body">
        <geom mass="0.11700" pos="0.00000 -0.83000 1.26467" size="0.08500 0.18500 0.05250" type="box"/>
      </body>
    </body>
  </worldbody>
  <tendon>
    <spatial range="0.27115 2.71155" stiffness="500">
      <site site="s1_1"/>
      <site site="s1_2"/>
    </spatial>
  </tendon>
  <tendon>
    <spatial range="0.27115 2.71155" stiffness="500">
      <site site="s2_1"/>
      <site site="s2_2"/>
    </spatial>
  </tendon>
  <tendon>
    <spatial range="0.27115 2.71155" stiffness="500">
      <site site="s3_1"/>
      <site site="s3_2"/>
    </spatial>
  </tendon>
  <tendon>
    <spatial range="0.27115 2.71155" stiffness="500">
      <site site="s4_1"/>
      <site site="s4_2"/>
    </spatial>
  </tendon>
  <actuator>
    <position forcelimited="true" forcerange="-50 50" gear="1" joint="shoulder_1" kp="254"/>
    <position forcelimited="true" forcerange="-50 50" gear="1" joint="shoulder_2" kp="254"/>
    <position forcelimited="true" forcerange="-50 50" gear="1" joint="shoulder_3" kp="254"/>
    <position forcelimited="true" forcerange="-50 50" gear="1" joint="shoulder_4" kp="254"/>
  </actuator>
  <sensor>
    <force site="sensor_1"/>
    <force site="sensor_2"/>
    <force site="sensor_3"/>
    <force site="sensor_4"/>
    <accelerometer site="sensor_torso"/>
  </sensor>
</mujoco>
