<sdf version="1.4">
  <world name="default">
    <model name="tigrillo">
      <static>False</static>
      <link name="body_front">
        <pose>0 0.8 2.15 0 0 0</pose>
        <inertial>
          <mass>0.179</mass>
          <inertia>
            <ixx>0.010889166666666669</ixx>
            <ixy>0</ixy>
            <ixz>0</ixz>
            <iyy>0.030579166666666664</iyy>
            <iyz>0</iyz>
            <izz>0.03878333333333333</izz>
          </inertia>
        </inertial>
        <collision name="body_frontcol">
          <geometry>
            <box>
              <size>1.4 0.8 0.3</size>
            </box>
          </geometry>
        </collision>
        <visual name="body_frontvis">
          <geometry>
            <box>
              <size>1.4 0.8 0.3</size>
            </box>
          </geometry>
          <material>
            <ambient>1 0 0 1</ambient>
            <diffuse>1 0 0 1</diffuse>
            <specular>1 0 0 1</specular>
            <emissive>0 0 0 0</emissive>
          </material>
        </visual>
      </link>
      <link name="body_middle">
        <pose>0 0 2.0125 0 0 0</pose>
        <inertial>
          <mass>0.03</mass>
          <inertia>
            <ixx>0.0016015625000000003</ixx>
            <ixy>0</ixy>
            <ixz>0</ixz>
            <iyy>0.0006265625</iyy>
            <iyz>0</iyz>
            <izz>0.0022250000000000004</izz>
          </inertia>
        </inertial>
        <collision name="body_middlecol">
          <geometry>
            <box>
              <size>0.5 0.8 0.025</size>
            </box>
          </geometry>
        </collision>
        <visual name="body_middlevis">
          <geometry>
            <box>
              <size>0.5 0.8 0.025</size>
            </box>
          </geometry>
          <material>
            <ambient>0 0 1 1</ambient>
            <diffuse>0 0 1 1</diffuse>
            <specular>0 0 1 1</specular>
            <emissive>0 0 0 0</emissive>
          </material>
        </visual>
      </link>
      <link name="body_hind">
        <pose>0 -0.7 2.125 0 0 0</pose>
        <inertial>
          <mass>0.179</mass>
          <inertia>
            <ixx>0.006302291666666666</ixx>
            <ixy>0</ixy>
            <ixz>0</ixz>
            <iyy>0.013014791666666668</iyy>
            <iyz>0</iyz>
            <izz>0.0174525</izz>
          </inertia>
        </inertial>
        <collision name="body_hindcol">
          <geometry>
            <box>
              <size>0.9 0.6 0.25</size>
            </box>
          </geometry>
        </collision>
        <visual name="body_hindvis">
          <geometry>
            <box>
              <size>0.9 0.6 0.25</size>
            </box>
          </geometry>
          <material>
            <ambient>1 0 0 1</ambient>
            <diffuse>1 0 0 1</diffuse>
            <specular>1 0 0 1</specular>
            <emissive>0 0 0 0</emissive>
          </material>
        </visual>
      </link>
      <link name="FLM">
        <pose>-0.52 0.8 1.7469999999999999 0 0 0</pose>
        <inertial>
          <mass>0.067</mass>
          <inertia>
            <ixx>0.0021531343333333333</ixx>
            <ixy>0</ixy>
            <ixz>0</ixz>
            <iyy>0.0021531343333333333</iyy>
            <iyz>0</iyz>
            <izz>0.0014471999999999998</izz>
          </inertia>
        </inertial>
        <collision name="FLM_col">
          <geometry>
            <box>
              <size>0.36 0.36 0.506</size>
            </box>
          </geometry>
        </collision>
        <visual name="FLM_vis">
          <geometry>
            <box>
              <size>0.36 0.36 0.506</size>
            </box>
          </geometry>
          <material>
            <ambient>0 1 0 1</ambient>
            <diffuse>0 1 0 1</diffuse>
            <specular>0 1 0 1</specular>
            <emissive>0 0 0 0</emissive>
          </material>
        </visual>
      </link>
      <link name="FLU">
        <pose>-0.745 0.8 1.67 0.4363323129985824 0 0</pose>
        <inertial>
          <pose>0 0 -0.35 0 0 0</pose>
          <mass>0.0035185837720205686</mass>
          <inertia>
            <ixx>0.00014508293753298144</ixx>
            <ixy>0</ixy>
            <ixz>0</ixz>
            <iyy>0.00014508293753298144</iyy>
            <iyz>0</iyz>
            <izz>2.814867017616455e-06</izz>
          </inertia>
        </inertial>
        <collision name="FLU_col">
          <pose>0 0 -0.35 0 0 0</pose>
          <geometry>
            <cylinder length="0.7" radius="0.04"/>
          </geometry>
        </collision>
        <visual name="FLU_vis">
          <pose>0 0 -0.35 0 0 0</pose>
          <geometry>
            <cylinder length="0.7" radius="0.04"/>
          </geometry>
          <material>
            <ambient>0 0 1 1</ambient>
            <diffuse>0 0 1 1</diffuse>
            <specular>0 0 1 1</specular>
            <emissive>0 0 0 0</emissive>
          </material>
        </visual>
      </link>
      <link name="FLD">
        <pose>-0.745 1.0958327832184898 1.0355845490743452 1.0220178564557332 0 0</pose>
        <inertial>
          <pose>0 0 0.07500000000000001 0 0 0</pose>
          <mass>0.004272566008882119</mass>
          <inertia>
            <ixx>0.0002589531048549971</ixx>
            <ixy>0</ixy>
            <ixz>0</ixz>
            <iyy>0.0002589531048549971</iyy>
            <iyz>0</iyz>
            <izz>3.4180528071056957e-06</izz>
          </inertia>
        </inertial>
        <collision name="FLD_col">
          <pose>0 0 0.07500000000000001 0 0 0</pose>
          <geometry>
            <cylinder length="0.85" radius="0.04"/>
          </geometry>
        </collision>
        <visual name="FLD_vis">
          <pose>0 0 0.07500000000000001 0 0 0</pose>
          <geometry>
            <cylinder length="0.85" radius="0.04"/>
          </geometry>
          <material>
            <ambient>0 1 0 1</ambient>
            <diffuse>0 1 0 1</diffuse>
            <specular>0 1 0 1</specular>
            <emissive>0 0 0 0</emissive>
          </material>
        </visual>
      </link>
      <link name="BLM">
        <pose>-0.27 -0.7 1.7469999999999999 0 0 0</pose>
        <inertial>
          <mass>0.067</mass>
          <inertia>
            <ixx>0.0021531343333333333</ixx>
            <ixy>0</ixy>
            <ixz>0</ixz>
            <iyy>0.0021531343333333333</iyy>
            <iyz>0</iyz>
            <izz>0.0014471999999999998</izz>
          </inertia>
        </inertial>
        <collision name="BLM_col">
          <geometry>
            <box>
              <size>0.36 0.36 0.506</size>
            </box>
          </geometry>
        </collision>
        <visual name="BLM_vis">
          <geometry>
            <box>
              <size>0.36 0.36 0.506</size>
            </box>
          </geometry>
          <material>
            <ambient>0 1 0 1</ambient>
            <diffuse>0 1 0 1</diffuse>
            <specular>0 1 0 1</specular>
            <emissive>0 0 0 0</emissive>
          </material>
        </visual>
      </link>
      <link name="BLU">
        <pose>-0.495 -0.7 1.67 0.0 0 0</pose>
        <inertial>
          <pose>0 0 -0.35 0 0 0</pose>
          <mass>0.0035185837720205686</mass>
          <inertia>
            <ixx>0.00014508293753298144</ixx>
            <ixy>0</ixy>
            <ixz>0</ixz>
            <iyy>0.00014508293753298144</iyy>
            <iyz>0</iyz>
            <izz>2.814867017616455e-06</izz>
          </inertia>
        </inertial>
        <collision name="BLU_col">
          <pose>0 0 -0.35 0 0 0</pose>
          <geometry>
            <cylinder length="0.7" radius="0.04"/>
          </geometry>
        </collision>
        <visual name="BLU_vis">
          <pose>0 0 -0.35 0 0 0</pose>
          <geometry>
            <cylinder length="0.7" radius="0.04"/>
          </geometry>
          <material>
            <ambient>0 0 1 1</ambient>
            <diffuse>0 0 1 1</diffuse>
            <specular>0 0 1 1</specular>
            <emissive>0 0 0 0</emissive>
          </material>
        </visual>
      </link>
      <link name="BLD">
        <pose>-0.495 -0.7 0.97 0.5856855434571508 0 0</pose>
        <inertial>
          <pose>0 0 0.07500000000000001 0 0 0</pose>
          <mass>0.004272566008882119</mass>
          <inertia>
            <ixx>0.0002589531048549971</ixx>
            <ixy>0</ixy>
            <ixz>0</ixz>
            <iyy>0.0002589531048549971</iyy>
            <iyz>0</iyz>
            <izz>3.4180528071056957e-06</izz>
          </inertia>
        </inertial>
        <collision name="BLD_col">
          <pose>0 0 0.07500000000000001 0 0 0</pose>
          <geometry>
            <cylinder length="0.85" radius="0.04"/>
          </geometry>
        </collision>
        <visual name="BLD_vis">
          <pose>0 0 0.07500000000000001 0 0 0</pose>
          <geometry>
            <cylinder length="0.85" radius="0.04"/>
          </geometry>
          <material>
            <ambient>0 1 0 1</ambient>
            <diffuse>0 1 0 1</diffuse>
            <specular>0 1 0 1</specular>
            <emissive>0 0 0 0</emissive>
          </material>
        </visual>
      </link>
      <link name="FRM">
        <pose>0.52 0.8 1.7469999999999999 0 0 0</pose>
        <inertial>
          <mass>0.067</mass>
          <inertia>
            <ixx>0.0021531343333333333</ixx>
            <ixy>0</ixy>
            <ixz>0</ixz>
            <iyy>0.0021531343333333333</iyy>
            <iyz>0</iyz>
            <izz>0.0014471999999999998</izz>
          </inertia>
        </inertial>
        <collision name="FRM_col">
          <geometry>
            <box>
              <size>0.36 0.36 0.506</size>
            </box>
          </geometry>
        </collision>
        <visual name="FRM_vis">
          <geometry>
            <box>
              <size>0.36 0.36 0.506</size>
            </box>
          </geometry>
          <material>
            <ambient>0 1 0 1</ambient>
            <diffuse>0 1 0 1</diffuse>
            <specular>0 1 0 1</specular>
            <emissive>0 0 0 0</emissive>
          </material>
        </visual>
      </link>
      <link name="FRU">
        <pose>0.745 0.8 1.67 0.4363323129985824 0 0</pose>
        <inertial>
          <pose>0 0 -0.35 0 0 0</pose>
          <mass>0.0035185837720205686</mass>
          <inertia>
            <ixx>0.00014508293753298144</ixx>
            <ixy>0</ixy>
            <ixz>0</ixz>
            <iyy>0.00014508293753298144</iyy>
            <iyz>0</iyz>
            <izz>2.814867017616455e-06</izz>
          </inertia>
        </inertial>
        <collision name="FRU_col">
          <pose>0 0 -0.35 0 0 0</pose>
          <geometry>
            <cylinder length="0.7" radius="0.04"/>
          </geometry>
        </collision>
        <visual name="FRU_vis">
          <pose>0 0 -0.35 0 0 0</pose>
          <geometry>
            <cylinder length="0.7" radius="0.04"/>
          </geometry>
          <material>
            <ambient>0 0 1 1</ambient>
            <diffuse>0 0 1 1</diffuse>
            <specular>0 0 1 1</specular>
            <emissive>0 0 0 0</emissive>
          </material>
        </visual>
      </link>
      <link name="FRD">
        <pose>0.745 1.0958327832184898 1.0355845490743452 1.0220178564557332 0 0</pose>
        <inertial>
          <pose>0 0 0.07500000000000001 0 0 0</pose>
          <mass>0.004272566008882119</mass>
          <inertia>
            <ixx>0.0002589531048549971</ixx>
            <ixy>0</ixy>
            <ixz>0</ixz>
            <iyy>0.0002589531048549971</iyy>
            <iyz>0</iyz>
            <izz>3.4180528071056957e-06</izz>
          </inertia>
        </inertial>
        <collision name="FRD_col">
          <pose>0 0 0.07500000000000001 0 0 0</pose>
          <geometry>
            <cylinder length="0.85" radius="0.04"/>
          </geometry>
        </collision>
        <visual name="FRD_vis">
          <pose>0 0 0.07500000000000001 0 0 0</pose>
          <geometry>
            <cylinder length="0.85" radius="0.04"/>
          </geometry>
          <material>
            <ambient>0 1 0 1</ambient>
            <diffuse>0 1 0 1</diffuse>
            <specular>0 1 0 1</specular>
            <emissive>0 0 0 0</emissive>
          </material>
        </visual>
      </link>
      <link name="BRM">
        <pose>0.27 -0.7 1.7469999999999999 0 0 0</pose>
        <inertial>
          <mass>0.067</mass>
          <inertia>
            <ixx>0.0021531343333333333</ixx>
            <ixy>0</ixy>
            <ixz>0</ixz>
            <iyy>0.0021531343333333333</iyy>
            <iyz>0</iyz>
            <izz>0.0014471999999999998</izz>
          </inertia>
        </inertial>
        <collision name="BRM_col">
          <geometry>
            <box>
              <size>0.36 0.36 0.506</size>
            </box>
          </geometry>
        </collision>
        <visual name="BRM_vis">
          <geometry>
            <box>
              <size>0.36 0.36 0.506</size>
            </box>
          </geometry>
          <material>
            <ambient>0 1 0 1</ambient>
            <diffuse>0 1 0 1</diffuse>
            <specular>0 1 0 1</specular>
            <emissive>0 0 0 0</emissive>
          </material>
        </visual>
      </link>
      <link name="BRU">
        <pose>0.495 -0.7 1.67 0.0 0 0</pose>
        <inertial>
          <pose>0 0 -0.35 0 0 0</pose>
          <mass>0.0035185837720205686</mass>
          <inertia>
            <ixx>0.00014508293753298144</ixx>
            <ixy>0</ixy>
            <ixz>0</ixz>
            <iyy>0.00014508293753298144</iyy>
            <iyz>0</iyz>
            <izz>2.814867017616455e-06</izz>
          </inertia>
        </inertial>
        <collision name="BRU_col">
          <pose>0 0 -0.35 0 0 0</pose>
          <geometry>
            <cylinder length="0.7" radius="0.04"/>
          </geometry>
        </collision>
        <visual name="BRU_vis">
          <pose>0 0 -0.35 0 0 0</pose>
          <geometry>
            <cylinder length="0.7" radius="0.04"/>
          </geometry>
          <material>
            <ambient>0 0 1 1</ambient>
            <diffuse>0 0 1 1</diffuse>
            <specular>0 0 1 1</specular>
            <emissive>0 0 0 0</emissive>
          </material>
        </visual>
      </link>
      <link name="BRD">
        <pose>0.495 -0.7 0.97 0.5856855434571508 0 0</pose>
        <inertial>
          <pose>0 0 0.07500000000000001 0 0 0</pose>
          <mass>0.004272566008882119</mass>
          <inertia>
            <ixx>0.0002589531048549971</ixx>
            <ixy>0</ixy>
            <ixz>0</ixz>
            <iyy>0.0002589531048549971</iyy>
            <iyz>0</iyz>
            <izz>3.4180528071056957e-06</izz>
          </inertia>
        </inertial>
        <collision name="BRD_col">
          <pose>0 0 0.07500000000000001 0 0 0</pose>
          <geometry>
            <cylinder length="0.85" radius="0.04"/>
          </geometry>
        </collision>
        <visual name="BRD_vis">
          <pose>0 0 0.07500000000000001 0 0 0</pose>
          <geometry>
            <cylinder length="0.85" radius="0.04"/>
          </geometry>
          <material>
            <ambient>0 1 0 1</ambient>
            <diffuse>0 1 0 1</diffuse>
            <specular>0 1 0 1</specular>
            <emissive>0 0 0 0</emissive>
          </material>
        </visual>
      </link>
      <joint name="body_front_J" type="fixed">
        <parent>body_middle</parent>
        <child>body_front</child>
      </joint>
      <joint name="body_hind_J" type="fixed">
        <parent>body_middle</parent>
        <child>body_hind</child>
      </joint>
      <joint name="FLMJ" type="fixed">
        <parent>body_front</parent>
        <child>FLM</child>
      </joint>
      <joint name="FLUJ" type="revolute">
        <parent>FLM</parent>
        <child>FLU</child>
        <axis>
          <xyz>1 0 0</xyz>
          <dynamics>
            <damping>0.2</damping>
          </dynamics>
          <limit>
            <lower>-2.007128639793479</lower>
            <upper>1.1344640137963142</upper>
          </limit>
        </axis>
      </joint>
      <joint name="FLDJ" type="fixed">
        <parent>FLU</parent>
        <child>FLD</child>
        <axis>
          <xyz>1 0 0</xyz>
          <dynamics>
            <damping>0.2</damping>
            <spring_stiffness>233.9349247139039</spring_stiffness>
          </dynamics>
          <limit>
            <lower>-0.1</lower>
            <upper>1.5707963267948966</upper>
          </limit>
        </axis>
      </joint>
      <joint name="BLMJ" type="fixed">
        <parent>body_hind</parent>
        <child>BLM</child>
      </joint>
      <joint name="BLUJ" type="revolute">
        <parent>BLM</parent>
        <child>BLU</child>
        <axis>
          <xyz>1 0 0</xyz>
          <dynamics>
            <damping>0.2</damping>
          </dynamics>
          <limit>
            <lower>-1.5707963267948966</lower>
            <upper>1.5707963267948966</upper>
          </limit>
        </axis>
      </joint>
      <joint name="BLDJ" type="fixed">
        <parent>BLU</parent>
        <child>BLD</child>
        <axis>
          <xyz>1 0 0</xyz>
          <dynamics>
            <damping>0.2</damping>
            <spring_stiffness>233.9349247139039</spring_stiffness>
          </dynamics>
          <limit>
            <lower>-0.1</lower>
            <upper>1.5707963267948966</upper>
          </limit>
        </axis>
      </joint>
      <joint name="FRMJ" type="fixed">
        <parent>body_front</parent>
        <child>FRM</child>
      </joint>
      <joint name="FRUJ" type="revolute">
        <parent>FRM</parent>
        <child>FRU</child>
        <axis>
          <xyz>1 0 0</xyz>
          <dynamics>
            <damping>0.2</damping>
          </dynamics>
          <limit>
            <lower>-2.007128639793479</lower>
            <upper>1.1344640137963142</upper>
          </limit>
        </axis>
      </joint>
      <joint name="FRDJ" type="fixed">
        <parent>FRU</parent>
        <child>FRD</child>
        <axis>
          <xyz>1 0 0</xyz>
          <dynamics>
            <damping>0.2</damping>
            <spring_stiffness>233.9349247139039</spring_stiffness>
          </dynamics>
          <limit>
            <lower>-0.1</lower>
            <upper>1.5707963267948966</upper>
          </limit>
        </axis>
      </joint>
      <joint name="BRMJ" type="fixed">
        <parent>body_hind</parent>
        <child>BRM</child>
      </joint>
      <joint name="BRUJ" type="revolute">
        <parent>BRM</parent>
        <child>BRU</child>
        <axis>
          <xyz>1 0 0</xyz>
          <dynamics>
            <damping>0.2</damping>
          </dynamics>
          <limit>
            <lower>-1.5707963267948966</lower>
            <upper>1.5707963267948966</upper>
          </limit>
        </axis>
      </joint>
      <joint name="BRDJ" type="fixed">
        <parent>BRU</parent>
        <child>BRD</child>
        <axis>
          <xyz>1 0 0</xyz>
          <dynamics>
            <damping>0.2</damping>
            <spring_stiffness>233.9349247139039</spring_stiffness>
          </dynamics>
          <limit>
            <lower>-0.1</lower>
            <upper>1.5707963267948966</upper>
          </limit>
        </axis>
      </joint>
    </model>
  </world>
</sdf>
